<?xml version="1.0" encoding="utf-8"?>
<!-- This URDF was automatically created by SolidWorks to URDF Exporter! Originally created by Stephen Brawner (brawner@gmail.com) 
     Commit Version: 1.6.0-4-g7f85cfe  Build Version: 1.6.7995.38578
     For more information, please see http://wiki.ros.org/sw_urdf_exporter -->
<robot name="finger">
  <link name="base_link">
    <inertial>
      <origin
        xyz="-0.00168969091187882 0.0278893702990069 0.0386697200522784" rpy="0 0 0" />
      <mass value="0.0119128649201374" />
      <inertia
        ixx="1.77903316958506E-06"
        ixy="2.73784518026717E-10"
        ixz="-7.4497368924376E-14"
        iyy="6.42440261427198E-07"
        iyz="5.2301061822394E-08"
        izz="1.46496018768648E-06" />
    </inertial>
    <visual>
      <origin
        xyz="0 0 0"
        rpy="0 0 0" />
      <geometry>
        <mesh
          filename="package://roborscht_description/meshes/base_link.STL" />
      </geometry>
      <material
        name="">
        <color rgba="0.8 0.8 0.8 1"/>
      </material>
    </visual>
    <collision>
      <origin
        xyz="0 0 0"
        rpy="0 0 0" />
      <geometry>
        <mesh
          filename="package://roborscht_description/meshes/base_link.STL" />
      </geometry>
    </collision>
  </link>
  <link
    name="metacarpal_link">
    <inertial>
      <origin
        xyz="2.55503054425767E-06 -0.0200961384807429 -0.00266508797552342"
        rpy="0 0 0" />
      <mass
        value="0.00537510095982113" />
      <inertia
        ixx="2.53059695492456E-07"
        ixy="1.87666699410734E-10"
        ixz="2.35484866530141E-11"
        iyy="1.08190456615305E-07"
        iyz="-2.20514612979224E-08"
        izz="2.05816365327712E-07" />
    </inertial>
    <visual>
      <origin
        xyz="0 0 0"
        rpy="0 0 0" />
      <geometry>
        <mesh
          filename="package://roborscht_description/meshes/metacarpal_link.STL" />
      </geometry>
      <material
        name="">
        <color rgba="0.8 0.8 0.8 1"/>
      </material>
    </visual>
    <collision>
      <origin
        xyz="0 0 0"
        rpy="0 0 0" />
      <geometry>
        <mesh
          filename="package://roborscht_description/meshes/metacarpal_link.STL" />
      </geometry>
    </collision>
  </link>
  <joint
    name="metacarpal_joint"
    type="revolute">
    <origin
      xyz="-0.0016899 -0.051494 0.059041"
      rpy="-1.5708 -0.049938 3.1416" />
    <parent link="base_link" />
    <child link="metacarpal_link" />
    <axis
      xyz="0 0 1" />
    <limit
      lower="-0.2618"
      upper="0.2618"
      effort="0"
      velocity="0" />
  </joint>
  <link
    name="proximal_link">
    <inertial>
      <origin
        xyz="0.0181492181193309 -0.00455519901217467 -6.55906348605729E-06"
        rpy="0 0 0" />
      <mass
        value="0.00457448104418533" />
      <inertia
        ixx="8.91294749858896E-08"
        ixy="-3.0111460101639E-09"
        ixz="-2.40839829626287E-10"
        iyy="1.28490345109158E-07"
        iyz="-1.11567188486128E-11"
        izz="1.8348738040492E-07" />
    </inertial>
    <visual>
      <origin
        xyz="0 0 0"
        rpy="0 0 0" />
      <geometry>
        <mesh
          filename="package://roborscht_description/meshes/proximal_link.STL" />
      </geometry>
      <material
        name="">
        <color rgba="0.8 0.8 0.8 1" />
      </material>
    </visual>
    <collision>
      <origin
        xyz="0 0 0"
        rpy="0 0 0" />
      <geometry>
        <mesh
          filename="package://roborscht_description/meshes/proximal_link.STL" />
      </geometry>
    </collision>
  </link>
  <joint
    name="proximal_joint"
    type="revolute">
    <origin
      xyz="0 -0.038786 -0.007734"
      rpy="-1.5708 0.085673 -1.5708" />
    <parent
      link="metacarpal_link" />
    <child
      link="proximal_link" />
    <axis
      xyz="0 0 1" />
    <limit
      lower="-1.309"
      upper="0"
      effort="0"
      velocity="0" />
  </joint>
  <link
    name="middle_link">
    <inertial>
      <origin
        xyz="0.0177672178272411 -0.004474805346593 -6.84025959544771E-06"
        rpy="0 0 0" />
      <mass
        value="0.00438641275668905" />
      <inertia
        ixx="8.46514986449752E-08"
        ixy="-3.01219917101257E-09"
        ixz="-2.30777500003745E-10"
        iyy="1.17446243228216E-07"
        iyz="-1.1103682095074E-11"
        izz="1.69859402394516E-07" />
    </inertial>
    <visual>
      <origin
        xyz="0 0 0"
        rpy="0 0 0" />
      <geometry>
        <mesh
          filename="package://roborscht_description/meshes/middle_link.STL" />
      </geometry>
      <material
        name="">
        <color rgba="0.8 0.8 0.8 1"/>
      </material>
    </visual>
    <collision>
      <origin
        xyz="0 0 0"
        rpy="0 0 0" />
      <geometry>
        <mesh
          filename="package://roborscht_description/meshes/middle_link.STL" />
      </geometry>
    </collision>
  </link>
  <joint
    name="middle_joint"
    type="revolute">
    <origin
      xyz="0.033972 0 0"
      rpy="0 0 -0.011388" />
    <parent
      link="proximal_link" />
    <child
      link="middle_link" />
    <axis
      xyz="0 0 1" />
    <limit
      lower="-1.309"
      upper="0"
      effort="0"
      velocity="0" />
    <mimic joint="proximal_joint" multiplier="1" offset="0" />
  </joint>
  <link
    name="distal_link">
    <inertial>
      <origin
        xyz="-0.0141234378639758 -0.00526492449893716 -0.000119344366734854"
        rpy="0 0 0" />
      <mass
        value="0.00324558485631147" />
      <inertia
        ixx="6.62419109034208E-08"
        ixy="-7.47834711523089E-09"
        ixz="3.87195824060538E-10"
        iyy="7.00049063251166E-08"
        iyz="-7.73951192286721E-10"
        izz="1.10271023940816E-07" />
    </inertial>
    <visual>
      <origin
        xyz="0 0 0"
        rpy="0 0 0" />
      <geometry>
        <mesh
          filename="package://roborscht_description/meshes/distal_link.STL" />
      </geometry>
      <material
        name="">
        <color rgba="0.8 0.8 0.8 1"/>
      </material>
    </visual>
    <collision>
      <origin
        xyz="0 0 0"
        rpy="0 0 0" />
      <geometry>
        <mesh
          filename="package://roborscht_description/meshes/distal_link.STL" />
      </geometry>
    </collision>
  </link>
  <joint
    name="distal_joint"
    type="revolute">
    <origin
      xyz="0.033172 0 0"
      rpy="-3.1416 0 3.0784" />
    <parent
      link="middle_link" />
    <child
      link="distal_link" />
    <axis
      xyz="0 0 -1" />
    <limit
      lower="-1.309"
      upper="0"
      effort="0"
      velocity="0" />
    <mimic joint="middle_joint" multiplier="1" offset="0" />
  </joint>
</robot>